<?xml version='1.0' encoding='utf-8'?>
<robot name="leg_assembly_left">
  <link name="link_leg_part_3_1">
    <visual>
      <origin xyz="0 0 0" rpy="0 0 0" />
      <geometry>
        <mesh filename="./meshes/leg_part_3_1.stl" />
        </geometry>
      <material name="link_leg_part_3_1_material">
        <color rgba="0.23137255 0.38039216 0.70588235 1" />
        </material>
      </visual>
    <collision>
      <origin xyz="0 0 0" rpy="0 0 0" />
      <geometry>
        <mesh filename="./meshes/leg_part_3_1.stl" />
        </geometry>
      </collision>
    <inertial>
      <mass value="0.1914504" />
      <inertia ixx="0.00043556748" iyy="0.00050360511" izz="0.00039339846" ixy="9.6383147e-05" ixz="0" iyz="0" />
      <origin xyz="0 0 0" rpy="-2.753668 -0.49098178 -0.7140939" />
      </inertial>
    </link>
  <link name="link_rmd_x8_90_mock_1_inner_rmd_x8_90_1">
    <visual>
      <origin xyz="0 0 0" rpy="0 0 0" />
      <geometry>
        <mesh filename="./meshes/rmd_x8_90_mock_1_inner_rmd_x8_90_1.stl" />
        </geometry>
      <material name="link_rmd_x8_90_mock_1_inner_rmd_x8_90_1_material">
        <color rgba="0.98039216 0.71372549 0.0039215686 1" />
        </material>
      </visual>
    <collision>
      <origin xyz="0 0 0" rpy="0 0 0" />
      <geometry>
        <mesh filename="./meshes/rmd_x8_90_mock_1_inner_rmd_x8_90_1.stl" />
        </geometry>
      </collision>
    <inertial>
      <mass value="0.35017331" />
      <inertia ixx="0.00020157869" iyy="0.00012756556" izz="0.00015223661" ixy="0" ixz="4.27315e-05" iyz="0" />
      <origin xyz="0.021650635 0.0125 0.011977659" rpy="3.1415927 0 3.1415927" />
      </inertial>
    </link>
  <joint name="joint_fastened_3" type="fixed">
    <origin xyz="-0.097659108 0.01745093 -0.01250002" rpy="1.5707963 0 0" />
    <parent link="link_leg_part_3_1" />
    <child link="link_rmd_x8_90_mock_1_inner_rmd_x8_90_1" />
    </joint>
  <link name="link_leg_part_4_1">
    <visual>
      <origin xyz="0 0 0" rpy="0 0 0" />
      <geometry>
        <mesh filename="./meshes/leg_part_4_1.stl" />
        </geometry>
      <material name="link_leg_part_4_1_material">
        <color rgba="0.64705882 0.64705882 0.64705882 1" />
        </material>
      </visual>
    <collision>
      <origin xyz="0 0 0" rpy="0 0 0" />
      <geometry>
        <mesh filename="./meshes/leg_part_4_1.stl" />
        </geometry>
      </collision>
    <inertial>
      <mass value="0.09299573" />
      <inertia ixx="8.6209079e-05" iyy="0.00017860969" izz="0.00025876717" ixy="0" ixz="0" iyz="0" />
      <origin xyz="-0.037174443 -0.060000019 -0.0098354041" rpy="0 0 0.0017096165" />
      </inertial>
    </link>
  <joint name="joint_fastened_4" type="fixed">
    <origin xyz="0.018991527 -0.05804907 -0.06000002" rpy="-1.5707963 0 0" />
    <parent link="link_leg_part_3_1" />
    <child link="link_leg_part_4_1" />
    </joint>
  <link name="link_rmd_x8_90_mock_2_outer_rmd_x8_90_1">
    <visual>
      <origin xyz="0 0 0" rpy="0 0 0" />
      <geometry>
        <mesh filename="./meshes/rmd_x8_90_mock_2_outer_rmd_x8_90_1.stl" />
        </geometry>
      <material name="link_rmd_x8_90_mock_2_outer_rmd_x8_90_1_material">
        <color rgba="0.49803922 0.49803922 0.49803922 1" />
        </material>
      </visual>
    <collision>
      <origin xyz="0 0 0" rpy="0 0 0" />
      <geometry>
        <mesh filename="./meshes/rmd_x8_90_mock_2_outer_rmd_x8_90_1.stl" />
        </geometry>
      </collision>
    <inertial>
      <mass value="0.49985879" />
      <inertia ixx="0.00048280871" iyy="0.00046437396" izz="0.00076940631" ixy="0" ixz="0" iyz="0" />
      <origin xyz="-0.044808157 0.018560146 -0.019942948" rpy="0 1.5707963 0" />
      </inertial>
    </link>
  <joint name="joint_fastened_5" type="fixed">
    <origin xyz="0.033991527 0.012861076 -0.044808178" rpy="-3.1415927 1.5707963 0" />
    <parent link="link_leg_part_3_1" />
    <child link="link_rmd_x8_90_mock_2_outer_rmd_x8_90_1" />
    </joint>
  <link name="link_rmd_x8_90_mock_1_outer_rmd_x8_90_1">
    <visual>
      <origin xyz="0 0 0" rpy="0 0 0" />
      <geometry>
        <mesh filename="./meshes/rmd_x8_90_mock_1_outer_rmd_x8_90_1.stl" />
        </geometry>
      <material name="link_rmd_x8_90_mock_1_outer_rmd_x8_90_1_material">
        <color rgba="0.49803922 0.49803922 0.49803922 1" />
        </material>
      </visual>
    <collision>
      <origin xyz="0 0 0" rpy="0 0 0" />
      <geometry>
        <mesh filename="./meshes/rmd_x8_90_mock_1_outer_rmd_x8_90_1.stl" />
        </geometry>
      </collision>
    <inertial>
      <mass value="0.49985879" />
      <inertia ixx="0.00048280871" iyy="0.00046437396" izz="0.00076940631" ixy="0" ixz="0" iyz="0" />
      <origin xyz="0 0 -0.027557052" rpy="3.1415927 -1.5707963 0" />
      </inertial>
    </link>
  <joint name="joint_rmd_x8_90_mock_1_dof_x8" type="revolute">
    <origin xyz="0.021650635 0.0125 0.0035" rpy="3.1415927 0 -2.0943951" />
    <parent link="link_rmd_x8_90_mock_1_inner_rmd_x8_90_1" />
    <child link="link_rmd_x8_90_mock_1_outer_rmd_x8_90_1" />
    <limit effort="90" velocity="5" lower="-1.0471976" upper="2.0943951" />
    <axis xyz="0 0 -1" />
    </joint>
  <link name="link_rmd_x8_90_mock_2_inner_rmd_x8_90_1">
    <visual>
      <origin xyz="0 0 0" rpy="0 0 0" />
      <geometry>
        <mesh filename="./meshes/rmd_x8_90_mock_2_inner_rmd_x8_90_1.stl" />
        </geometry>
      <material name="link_rmd_x8_90_mock_2_inner_rmd_x8_90_1_material">
        <color rgba="0.98039216 0.71372549 0.0039215686 1" />
        </material>
      </visual>
    <collision>
      <origin xyz="0 0 0" rpy="0 0 0" />
      <geometry>
        <mesh filename="./meshes/rmd_x8_90_mock_2_inner_rmd_x8_90_1.stl" />
        </geometry>
      </collision>
    <inertial>
      <mass value="0.35017331" />
      <inertia ixx="0.00012756556" iyy="0.00012756556" izz="0.00022624974" ixy="0" ixz="0" iyz="0" />
      <origin xyz="0 0 -0.0084776592" rpy="3.1415927 0 0" />
      </inertial>
    </link>
  <joint name="joint_rmd_x8_90_mock_2_dof_x8" type="revolute">
    <origin xyz="-0.044808157 0.018560146 -0.0475" rpy="3.1415927 0 0" />
    <parent link="link_rmd_x8_90_mock_2_outer_rmd_x8_90_1" />
    <child link="link_rmd_x8_90_mock_2_inner_rmd_x8_90_1" />
    <limit effort="90" velocity="5" lower="-3.1415927" upper="0" />
    <axis xyz="0 0 -1" />
    </joint>
  <link name="link_leg_part_2_left_1">
    <visual>
      <origin xyz="0 0 0" rpy="0 0 0" />
      <geometry>
        <mesh filename="./meshes/leg_part_2_left_1.stl" />
        </geometry>
      <material name="link_leg_part_2_left_1_material">
        <color rgba="0.64705882 0.64705882 0.64705882 1" />
        </material>
      </visual>
    <collision>
      <origin xyz="0 0 0" rpy="0 0 0" />
      <geometry>
        <mesh filename="./meshes/leg_part_2_left_1.stl" />
        </geometry>
      </collision>
    <inertial>
      <mass value="0.23289661" />
      <inertia ixx="0.0006932322" iyy="0.00049537603" izz="0.0009832984" ixy="-9.3648936e-06" ixz="-2.5858642e-06" iyz="-3.4541587e-05" />
      <origin xyz="0.01804262 -0.059496449 -0.015787305" rpy="-0.0046017221 0.063692797 -0.067107728" />
      </inertial>
    </link>
  <joint name="joint_fastened_2" type="fixed">
    <origin xyz="-0.018560146 -0.044808157 -0.0475" rpy="3.1415927 0 0" />
    <parent link="link_rmd_x8_90_mock_1_outer_rmd_x8_90_1" />
    <child link="link_leg_part_2_left_1" />
    </joint>
  <link name="link_let_part_5_left_1">
    <visual>
      <origin xyz="0 0 0" rpy="0 0 0" />
      <geometry>
        <mesh filename="./meshes/let_part_5_left_1.stl" />
        </geometry>
      <material name="link_let_part_5_left_1_material">
        <color rgba="0.64705882 0.64705882 0.64705882 1" />
        </material>
      </visual>
    <collision>
      <origin xyz="0 0 0" rpy="0 0 0" />
      <geometry>
        <mesh filename="./meshes/let_part_5_left_1.stl" />
        </geometry>
      </collision>
    <inertial>
      <mass value="0.28898133" />
      <inertia ixx="0.0013254719" iyy="0.0007160887" izz="0.00083314579" ixy="0" ixz="-5.4255244e-05" iyz="-2.9416279e-05" />
      <origin xyz="0.017475327 0.0012376983 -0.063202954" rpy="1.3266757 -0.10647641 1.5930957" />
      </inertial>
    </link>
  <joint name="joint_fastened_92" type="fixed">
    <origin xyz="0 0 0.0035" rpy="3.1415927 0 3.1415927" />
    <parent link="link_rmd_x8_90_mock_2_inner_rmd_x8_90_1" />
    <child link="link_let_part_5_left_1" />
    </joint>
  <link name="link_rmd_x12_150_mock_1_inner_x12_150_1">
    <visual>
      <origin xyz="0 0 0" rpy="0 0 0" />
      <geometry>
        <mesh filename="./meshes/rmd_x12_150_mock_1_inner_x12_150_1.stl" />
        </geometry>
      <material name="link_rmd_x12_150_mock_1_inner_x12_150_1_material">
        <color rgba="0.23137255 0.38039216 0.70588235 1" />
        </material>
      </visual>
    <collision>
      <origin xyz="0 0 0" rpy="0 0 0" />
      <geometry>
        <mesh filename="./meshes/rmd_x12_150_mock_1_inner_x12_150_1.stl" />
        </geometry>
      </collision>
    <inertial>
      <mass value="0.1494739" />
      <inertia ixx="4.1852816e-05" iyy="4.1852816e-05" izz="7.1701209e-05" ixy="0" ixz="0" iyz="0" />
      <origin xyz="0 0.0185 0.012141029" rpy="3.1415927 0 0" />
      </inertial>
    </link>
  <joint name="joint_fastened_1" type="fixed">
    <origin xyz="0.036429774 -0.12330816 -0.023061848" rpy="1.5707963 -1.5707963 0" />
    <parent link="link_leg_part_2_left_1" />
    <child link="link_rmd_x12_150_mock_1_inner_x12_150_1" />
    </joint>
  <link name="link_rmd_x8_90_mock_3_outer_rmd_x8_90_1">
    <visual>
      <origin xyz="0 0 0" rpy="0 0 0" />
      <geometry>
        <mesh filename="./meshes/rmd_x8_90_mock_3_outer_rmd_x8_90_1.stl" />
        </geometry>
      <material name="link_rmd_x8_90_mock_3_outer_rmd_x8_90_1_material">
        <color rgba="0.49803922 0.49803922 0.49803922 1" />
        </material>
      </visual>
    <collision>
      <origin xyz="0 0 0" rpy="0 0 0" />
      <geometry>
        <mesh filename="./meshes/rmd_x8_90_mock_3_outer_rmd_x8_90_1.stl" />
        </geometry>
      </collision>
    <inertial>
      <mass value="0.49985879" />
      <inertia ixx="0.00048280871" iyy="0.00046437396" izz="0.00076940631" ixy="0" ixz="0" iyz="0" />
      <origin xyz="-0.018560146 0.044808157 -0.019942948" rpy="0 1.5707963 0" />
      </inertial>
    </link>
  <joint name="joint_fastened_91" type="fixed">
    <origin xyz="0.02685 0.044808157 -0.10493985" rpy="-3.1415927 -1.5707963 0" />
    <parent link="link_let_part_5_left_1" />
    <child link="link_rmd_x8_90_mock_3_outer_rmd_x8_90_1" />
    </joint>
  <link name="link_rmd_x12_150_mock_1_outer_x12_150_1">
    <visual>
      <origin xyz="0 0 0" rpy="0 0 0" />
      <geometry>
        <mesh filename="./meshes/rmd_x12_150_mock_1_outer_x12_150_1.stl" />
        </geometry>
      <material name="link_rmd_x12_150_mock_1_outer_x12_150_1_material">
        <color rgba="0.64705882 0.64705882 0.64705882 1" />
        </material>
      </visual>
    <collision>
      <origin xyz="0 0 0" rpy="0 0 0" />
      <geometry>
        <mesh filename="./meshes/rmd_x12_150_mock_1_outer_x12_150_1.stl" />
        </geometry>
      </collision>
    <inertial>
      <mass value="1.1505225" />
      <inertia ixx="0.0013578926" iyy="0.0013275542" izz="0.0021889818" ixy="0" ixz="0" iyz="0" />
      <origin xyz="-1.5243254e-05 0 0.0086023019" rpy="3.1410042 0 3.1410042" />
      </inertial>
    </link>
  <joint name="joint_rmd_x12_150_mock_1_dof_x12" type="revolute">
    <origin xyz="0 0.0185 0.023" rpy="0 0 0" />
    <parent link="link_rmd_x12_150_mock_1_inner_x12_150_1" />
    <child link="link_rmd_x12_150_mock_1_outer_x12_150_1" />
    <limit effort="80" velocity="5" lower="-4.712389" upper="4.712389" />
    <axis xyz="0 0 -1" />
    </joint>
  <link name="link_rmd_x8_90_mock_3_inner_rmd_x8_90_1">
    <visual>
      <origin xyz="0 0 0" rpy="0 0 0" />
      <geometry>
        <mesh filename="./meshes/rmd_x8_90_mock_3_inner_rmd_x8_90_1.stl" />
        </geometry>
      <material name="link_rmd_x8_90_mock_3_inner_rmd_x8_90_1_material">
        <color rgba="0.98039216 0.71372549 0.0039215686 1" />
        </material>
      </visual>
    <collision>
      <origin xyz="0 0 0" rpy="0 0 0" />
      <geometry>
        <mesh filename="./meshes/rmd_x8_90_mock_3_inner_rmd_x8_90_1.stl" />
        </geometry>
      </collision>
    <inertial>
      <mass value="0.35017331" />
      <inertia ixx="0.00012756556" iyy="0.00012756556" izz="0.00022624974" ixy="0" ixz="0" iyz="0" />
      <origin xyz="0 0 -0.0084776592" rpy="3.1415927 0 0" />
      </inertial>
    </link>
  <joint name="joint_rmd_x8_90_mock_3_dof_x8" type="revolute">
    <origin xyz="-0.018560146 0.044808157 -0.0475" rpy="3.1415927 0 0" />
    <parent link="link_rmd_x8_90_mock_3_outer_rmd_x8_90_1" />
    <child link="link_rmd_x8_90_mock_3_inner_rmd_x8_90_1" />
    <limit effort="90" velocity="5" lower="-4.712389" upper="4.712389" />
    <axis xyz="0 0 -1" />
    </joint>
  <link name="link_leg_part_1_2">
    <visual>
      <origin xyz="0 0 0" rpy="0 0 0" />
      <geometry>
        <mesh filename="./meshes/leg_part_1_2.stl" />
        </geometry>
      <material name="link_leg_part_1_2_material">
        <color rgba="0.61568627 0.81176471 0.92941176 1" />
        </material>
      </visual>
    <collision>
      <origin xyz="0 0 0" rpy="0 0 0" />
      <geometry>
        <mesh filename="./meshes/leg_part_1_2.stl" />
        </geometry>
      </collision>
    <inertial>
      <mass value="0.18740424" />
      <inertia ixx="0.00050512115" iyy="0.00086371009" izz="0.00049678333" ixy="-8.1028268e-05" ixz="0" iyz="0" />
      <origin xyz="-0.0071596031 -0.0055805032 0.00099867745" rpy="-0.21686582 -0.20732123 -3.0962541" />
      </inertial>
    </link>
  <joint name="joint_fastened_12" type="fixed">
    <origin xyz="-0.057556396 -0.0071596999 0.0245" rpy="3.1415927 0 -1.5707963" />
    <parent link="link_rmd_x12_150_mock_1_outer_x12_150_1" />
    <child link="link_leg_part_1_2" />
    </joint>
  </robot>
